INFO     2024-03-10 20:59:44.866 request id: app - uvicorn.server:serve - Started server process [6193]
INFO     2024-03-10 20:59:45.874 request id: app - uvicorn.lifespan.on:startup - Waiting for application startup.
INFO     2024-03-10 20:59:46.879 request id: app - uvicorn.lifespan.on:startup - Application startup complete.
INFO     2024-03-10 21:01:58.087 request id: app - uvicorn.protocols.http.h11_impl:send - 127.0.0.1:46918 - "GET / HTTP/1.1" 404
INFO     2024-03-10 21:01:59.103 request id: app - uvicorn.protocols.http.h11_impl:send - 127.0.0.1:46920 - "GET / HTTP/1.1" 404
INFO     2024-03-10 21:01:59.107 request id: app - uvicorn.protocols.http.h11_impl:send - 127.0.0.1:46922 - "GET / HTTP/1.1" 404
INFO     2024-03-10 21:02:00.732 request id: app - uvicorn.protocols.http.h11_impl:send - 127.0.0.1:46918 - "GET /favicon.ico HTTP/1.1" 404
INFO     2024-03-10 21:02:00.842 request id: app - uvicorn.protocols.http.h11_impl:send - 127.0.0.1:46920 - "GET /favicon.ico HTTP/1.1" 404
INFO     2024-03-10 21:02:00.918 request id: app - uvicorn.protocols.http.h11_impl:send - 127.0.0.1:46922 - "GET /favicon.ico HTTP/1.1" 404
INFO     2024-03-10 21:02:03.429 request id: app - uvicorn.protocols.http.h11_impl:send - 127.0.0.1:46918 - "GET / HTTP/1.1" 404
INFO     2024-03-10 21:02:04.467 request id: app - uvicorn.protocols.http.h11_impl:send - 127.0.0.1:46920 - "GET / HTTP/1.1" 404
INFO     2024-03-10 21:02:04.484 request id: app - uvicorn.protocols.http.h11_impl:send - 127.0.0.1:46922 - "GET / HTTP/1.1" 404
INFO     2024-03-10 21:02:04.511 request id: app - uvicorn.protocols.http.h11_impl:send - 127.0.0.1:50786 - "GET / HTTP/1.1" 404
INFO     2024-03-10 21:02:05.061 request id: app - uvicorn.protocols.http.h11_impl:send - 127.0.0.1:46918 - "GET /favicon.ico HTTP/1.1" 404
INFO     2024-03-10 21:02:05.088 request id: app - uvicorn.protocols.http.h11_impl:send - 127.0.0.1:46920 - "GET /favicon.ico HTTP/1.1" 404
INFO     2024-03-10 21:02:05.097 request id: app - uvicorn.protocols.http.h11_impl:send - 127.0.0.1:46922 - "GET /favicon.ico HTTP/1.1" 404
INFO     2024-03-10 21:02:05.107 request id: app - uvicorn.protocols.http.h11_impl:send - 127.0.0.1:50786 - "GET /favicon.ico HTTP/1.1" 404
INFO     2024-03-10 21:02:05.470 request id: app - uvicorn.protocols.http.h11_impl:send - 127.0.0.1:46918 - "GET / HTTP/1.1" 404
INFO     2024-03-10 21:02:06.072 request id: app - uvicorn.protocols.http.h11_impl:send - 127.0.0.1:46920 - "GET /favicon.ico HTTP/1.1" 404
INFO     2024-03-10 21:02:13.579 request id: app - uvicorn.protocols.http.h11_impl:send - 127.0.0.1:48712 - "GET /docs HTTP/1.1" 200
INFO     2024-03-10 21:02:14.672 request id: app - uvicorn.protocols.http.h11_impl:send - 127.0.0.1:48708 - "GET /static/swagger-ui.css HTTP/1.1" 200
INFO     2024-03-10 21:02:14.680 request id: app - uvicorn.protocols.http.h11_impl:send - 127.0.0.1:48712 - "GET /static/swagger-ui-bundle.js HTTP/1.1" 200
INFO     2024-03-10 21:02:15.497 request id: app - uvicorn.protocols.http.h11_impl:send - 127.0.0.1:48708 - "GET /openapi.json HTTP/1.1" 200
INFO     2024-03-10 21:08:55.441 request id: app - uvicorn.server:shutdown - Shutting down
INFO     2024-03-11 10:04:44.072 request id: app - uvicorn.server:serve - Started server process [2874]
INFO     2024-03-11 10:04:45.090 request id: app - uvicorn.lifespan.on:startup - Waiting for application startup.
INFO     2024-03-11 10:04:46.093 request id: app - uvicorn.lifespan.on:startup - Application startup complete.
INFO     2024-03-11 10:04:59.788 request id: app - uvicorn.protocols.http.h11_impl:send - 127.0.0.1:57204 - "GET / HTTP/1.1" 404
INFO     2024-03-11 10:05:01.561 request id: app - uvicorn.protocols.http.h11_impl:send - 127.0.0.1:57204 - "GET /favicon.ico HTTP/1.1" 404
INFO     2024-03-11 10:05:44.789 request id: app - rbl_fastapi_base.base.base_router:custom_route_handler - {'headers': {'content-type': 'application/json'}, 'request_body': {'email': 'admin@rabiloo.com', 'password': 'Rabiloo@123'}}
ERROR    2024-03-11 10:05:45.854 request id: app - app.src.exceptions.exception_handler:business_exception_handler - Database Error
{'data': 'Traceback (most recent call last):\n  File "/home/truongtuananh/anaconda3/envs/resource-management/lib/python3.10/site-packages/sqlalchemy/engine/base.py", line 145, in __init__\n    self._dbapi_connection = engine.raw_connection()\n  File "/home/truongtuananh/anaconda3/envs/resource-management/lib/python3.10/site-packages/sqlalchemy/engine/base.py", line 3275, in raw_connection\n    return self.pool.connect()\n  File "/home/truongtuananh/anaconda3/envs/resource-management/lib/python3.10/site-packages/sqlalchemy/pool/base.py", line 455, in connect\n    return _ConnectionFairy._checkout(self)\n  File "/home/truongtuananh/anaconda3/envs/resource-management/lib/python3.10/site-packages/sqlalchemy/pool/base.py", line 1271, in _checkout\n    fairy = _ConnectionRecord.checkout(pool)\n  File "/home/truongtuananh/anaconda3/envs/resource-management/lib/python3.10/site-packages/sqlalchemy/pool/base.py", line 719, in checkout\n    rec = pool._do_get()\n  File "/home/truongtuananh/anaconda3/envs/resource-management/lib/python3.10/site-packages/sqlalchemy/pool/impl.py", line 168, in _do_get\n    with util.safe_reraise():\n  File "/home/truongtuananh/anaconda3/envs/resource-management/lib/python3.10/site-packages/sqlalchemy/util/langhelpers.py", line 147, in __exit__\n    raise exc_value.with_traceback(exc_tb)\n  File "/home/truongtuananh/anaconda3/envs/resource-management/lib/python3.10/site-packages/sqlalchemy/pool/impl.py", line 166, in _do_get\n    return self._create_connection()\n  File "/home/truongtuananh/anaconda3/envs/resource-management/lib/python3.10/site-packages/sqlalchemy/pool/base.py", line 396, in _create_connection\n    return _ConnectionRecord(self)\n  File "/home/truongtuananh/anaconda3/envs/resource-management/lib/python3.10/site-packages/sqlalchemy/pool/base.py", line 681, in __init__\n    self.__connect()\n  File "/home/truongtuananh/anaconda3/envs/resource-management/lib/python3.10/site-packages/sqlalchemy/pool/base.py", line 905, in __connect\n    with util.safe_reraise():\n  File "/home/truongtuananh/anaconda3/envs/resource-management/lib/python3.10/site-packages/sqlalchemy/util/langhelpers.py", line 147, in __exit__\n    raise exc_value.with_traceback(exc_tb)\n  File "/home/truongtuananh/anaconda3/envs/resource-management/lib/python3.10/site-packages/sqlalchemy/pool/base.py", line 901, in __connect\n    self.dbapi_connection = connection = pool._invoke_creator(self)\n  File "/home/truongtuananh/anaconda3/envs/resource-management/lib/python3.10/site-packages/sqlalchemy/engine/create.py", line 641, in connect\n    return dialect.connect(*cargs, **cparams)\n  File "/home/truongtuananh/anaconda3/envs/resource-management/lib/python3.10/site-packages/sqlalchemy/engine/default.py", line 580, in connect\n    return self.loaded_dbapi.connect(*cargs, **cparams)\n  File "/home/truongtuananh/anaconda3/envs/resource-management/lib/python3.10/site-packages/psycopg2/__init__.py", line 122, in connect\n    conn = _connect(dsn, connection_factory=connection_factory, **kwasync)\npsycopg2.OperationalError: connection to server at "192.168.127.129", port 5432 failed: Connection refused\n\tIs the server running on that host and accepting TCP/IP connections?\n\n\nThe above exception was the direct cause of the following exception:\n\nTraceback (most recent call last):\n  File "/home/truongtuananh/Downloads/resource-management/app/../app/src/repositories/user_system.py", line 29, in get_user_by_email\n    self.model.is_deleted.is_(False)).first()\n  File "/home/truongtuananh/anaconda3/envs/resource-management/lib/python3.10/site-packages/sqlalchemy/orm/query.py", line 2752, in first\n    return self.limit(1)._iter().first()  # type: ignore\n  File "/home/truongtuananh/anaconda3/envs/resource-management/lib/python3.10/site-packages/sqlalchemy/orm/query.py", line 2855, in _iter\n    result: Union[ScalarResult[_T], Result[_T]] = self.session.execute(\n  File "/home/truongtuananh/anaconda3/envs/resource-management/lib/python3.10/site-packages/sqlalchemy/orm/session.py", line 2229, in execute\n    return self._execute_internal(\n  File "/home/truongtuananh/anaconda3/envs/resource-management/lib/python3.10/site-packages/sqlalchemy/orm/session.py", line 2114, in _execute_internal\n    conn = self._connection_for_bind(bind)\n  File "/home/truongtuananh/anaconda3/envs/resource-management/lib/python3.10/site-packages/sqlalchemy/orm/session.py", line 1981, in _connection_for_bind\n    return trans._connection_for_bind(engine, execution_options)\n  File "<string>", line 2, in _connection_for_bind\n  File "/home/truongtuananh/anaconda3/envs/resource-management/lib/python3.10/site-packages/sqlalchemy/orm/state_changes.py", line 137, in _go\n    ret_value = fn(self, *arg, **kw)\n  File "/home/truongtuananh/anaconda3/envs/resource-management/lib/python3.10/site-packages/sqlalchemy/orm/session.py", line 1108, in _connection_for_bind\n    conn = bind.connect()\n  File "/home/truongtuananh/anaconda3/envs/resource-management/lib/python3.10/site-packages/sqlalchemy/engine/base.py", line 3251, in connect\n    return self._connection_cls(self)\n  File "/home/truongtuananh/anaconda3/envs/resource-management/lib/python3.10/site-packages/sqlalchemy/engine/base.py", line 147, in __init__\n    Connection._handle_dbapi_exception_noconnection(\n  File "/home/truongtuananh/anaconda3/envs/resource-management/lib/python3.10/site-packages/sqlalchemy/engine/base.py", line 2413, in _handle_dbapi_exception_noconnection\n    raise sqlalchemy_exception.with_traceback(exc_info[2]) from e\n  File "/home/truongtuananh/anaconda3/envs/resource-management/lib/python3.10/site-packages/sqlalchemy/engine/base.py", line 145, in __init__\n    self._dbapi_connection = engine.raw_connection()\n  File "/home/truongtuananh/anaconda3/envs/resource-management/lib/python3.10/site-packages/sqlalchemy/engine/base.py", line 3275, in raw_connection\n    return self.pool.connect()\n  File "/home/truongtuananh/anaconda3/envs/resource-management/lib/python3.10/site-packages/sqlalchemy/pool/base.py", line 455, in connect\n    return _ConnectionFairy._checkout(self)\n  File "/home/truongtuananh/anaconda3/envs/resource-management/lib/python3.10/site-packages/sqlalchemy/pool/base.py", line 1271, in _checkout\n    fairy = _ConnectionRecord.checkout(pool)\n  File "/home/truongtuananh/anaconda3/envs/resource-management/lib/python3.10/site-packages/sqlalchemy/pool/base.py", line 719, in checkout\n    rec = pool._do_get()\n  File "/home/truongtuananh/anaconda3/envs/resource-management/lib/python3.10/site-packages/sqlalchemy/pool/impl.py", line 168, in _do_get\n    with util.safe_reraise():\n  File "/home/truongtuananh/anaconda3/envs/resource-management/lib/python3.10/site-packages/sqlalchemy/util/langhelpers.py", line 147, in __exit__\n    raise exc_value.with_traceback(exc_tb)\n  File "/home/truongtuananh/anaconda3/envs/resource-management/lib/python3.10/site-packages/sqlalchemy/pool/impl.py", line 166, in _do_get\n    return self._create_connection()\n  File "/home/truongtuananh/anaconda3/envs/resource-management/lib/python3.10/site-packages/sqlalchemy/pool/base.py", line 396, in _create_connection\n    return _ConnectionRecord(self)\n  File "/home/truongtuananh/anaconda3/envs/resource-management/lib/python3.10/site-packages/sqlalchemy/pool/base.py", line 681, in __init__\n    self.__connect()\n  File "/home/truongtuananh/anaconda3/envs/resource-management/lib/python3.10/site-packages/sqlalchemy/pool/base.py", line 905, in __connect\n    with util.safe_reraise():\n  File "/home/truongtuananh/anaconda3/envs/resource-management/lib/python3.10/site-packages/sqlalchemy/util/langhelpers.py", line 147, in __exit__\n    raise exc_value.with_traceback(exc_tb)\n  File "/home/truongtuananh/anaconda3/envs/resource-management/lib/python3.10/site-packages/sqlalchemy/pool/base.py", line 901, in __connect\n    self.dbapi_connection = connection = pool._invoke_creator(self)\n  File "/home/truongtuananh/anaconda3/envs/resource-management/lib/python3.10/site-packages/sqlalchemy/engine/create.py", line 641, in connect\n    return dialect.connect(*cargs, **cparams)\n  File "/home/truongtuananh/anaconda3/envs/resource-management/lib/python3.10/site-packages/sqlalchemy/engine/default.py", line 580, in connect\n    return self.loaded_dbapi.connect(*cargs, **cparams)\n  File "/home/truongtuananh/anaconda3/envs/resource-management/lib/python3.10/site-packages/psycopg2/__init__.py", line 122, in connect\n    conn = _connect(dsn, connection_factory=connection_factory, **kwasync)\nsqlalchemy.exc.OperationalError: (psycopg2.OperationalError) connection to server at "192.168.127.129", port 5432 failed: Connection refused\n\tIs the server running on that host and accepting TCP/IP connections?\n\n(Background on this error at: https://sqlalche.me/e/20/e3q8)\n'}
INFO     2024-03-11 10:05:45.859 request id: app - uvicorn.protocols.http.h11_impl:send - 127.0.0.1:35556 - "POST /rms/v1.0/login/access-token HTTP/1.1" 500
INFO     2024-03-11 23:31:03.395 request id: app - uvicorn.server:shutdown - Shutting down
INFO     2024-03-11 23:31:04.549 request id: app - uvicorn.lifespan.on:shutdown - Waiting for application shutdown.
INFO     2024-03-11 23:31:04.558 request id: app - uvicorn.lifespan.on:shutdown - Application shutdown complete.
INFO     2024-03-11 23:31:04.569 request id: app - uvicorn.server:serve - Finished server process [2874]
INFO     2024-03-11 23:47:23.937 request id: app - uvicorn.server:serve - Started server process [5116]
INFO     2024-03-11 23:47:24.940 request id: app - uvicorn.lifespan.on:startup - Waiting for application startup.
INFO     2024-03-11 23:47:25.944 request id: app - uvicorn.lifespan.on:startup - Application startup complete.
INFO     2024-03-11 23:48:22.530 request id: app - uvicorn.protocols.http.h11_impl:send - 127.0.0.1:51896 - "GET /docs HTTP/1.1" 200
INFO     2024-03-11 23:48:23.685 request id: app - uvicorn.protocols.http.h11_impl:send - 127.0.0.1:51896 - "GET /static/swagger-ui.css HTTP/1.1" 304
INFO     2024-03-11 23:48:23.692 request id: app - uvicorn.protocols.http.h11_impl:send - 127.0.0.1:51902 - "GET /static/swagger-ui-bundle.js HTTP/1.1" 304
INFO     2024-03-11 23:48:24.370 request id: app - uvicorn.protocols.http.h11_impl:send - 127.0.0.1:51902 - "GET /openapi.json HTTP/1.1" 200
INFO     2024-03-11 23:48:31.713 request id: app - uvicorn.protocols.http.h11_impl:send - 127.0.0.1:44872 - "GET / HTTP/1.1" 404
INFO     2024-03-11 23:48:32.864 request id: app - uvicorn.protocols.http.h11_impl:send - 127.0.0.1:44872 - "GET /favicon.ico HTTP/1.1" 404
INFO     2024-03-11 23:52:08.310 request id: app - uvicorn.server:shutdown - Shutting down
INFO     2024-03-14 18:49:40.690 request id: app - uvicorn.server:serve - Started server process [3694]
INFO     2024-03-14 18:49:41.695 request id: app - uvicorn.lifespan.on:startup - Waiting for application startup.
INFO     2024-03-14 18:49:42.697 request id: app - uvicorn.lifespan.on:startup - Application startup complete.
INFO     2024-03-14 18:49:55.353 request id: app - uvicorn.protocols.http.h11_impl:send - 127.0.0.1:60208 - "GET / HTTP/1.1" 404
INFO     2024-03-14 18:49:56.395 request id: app - uvicorn.protocols.http.h11_impl:send - 127.0.0.1:60220 - "GET / HTTP/1.1" 404
INFO     2024-03-14 18:49:56.399 request id: app - uvicorn.protocols.http.h11_impl:send - 127.0.0.1:60224 - "GET / HTTP/1.1" 404
INFO     2024-03-14 18:49:57.835 request id: app - uvicorn.protocols.http.h11_impl:send - 127.0.0.1:60208 - "GET /favicon.ico HTTP/1.1" 404
INFO     2024-03-14 18:50:04.748 request id: app - uvicorn.protocols.http.h11_impl:send - 127.0.0.1:43968 - "GET /docs HTTP/1.1" 200
INFO     2024-03-14 18:50:05.949 request id: app - uvicorn.protocols.http.h11_impl:send - 127.0.0.1:43968 - "GET /static/swagger-ui.css HTTP/1.1" 304
INFO     2024-03-14 18:50:05.964 request id: app - uvicorn.protocols.http.h11_impl:send - 127.0.0.1:43978 - "GET /static/swagger-ui-bundle.js HTTP/1.1" 304
INFO     2024-03-14 18:50:07.236 request id: app - uvicorn.protocols.http.h11_impl:send - 127.0.0.1:43978 - "GET /openapi.json HTTP/1.1" 200
INFO     2024-03-14 18:50:40.328 request id: app - rbl_fastapi_base.base.base_router:custom_route_handler - {'headers': {'content-type': 'application/json'}, 'request_body': {'email': 'admin@rabiloo.com', 'password': 'Rabiloo@123'}}
ERROR    2024-03-14 18:50:41.628 request id: app - app.src.exceptions.exception_handler:business_exception_handler - Database Error
{'data': 'Traceback (most recent call last):\n  File "/home/truongtuananh/anaconda3/envs/resource-management/lib/python3.10/site-packages/sqlalchemy/engine/base.py", line 145, in __init__\n    self._dbapi_connection = engine.raw_connection()\n  File "/home/truongtuananh/anaconda3/envs/resource-management/lib/python3.10/site-packages/sqlalchemy/engine/base.py", line 3275, in raw_connection\n    return self.pool.connect()\n  File "/home/truongtuananh/anaconda3/envs/resource-management/lib/python3.10/site-packages/sqlalchemy/pool/base.py", line 455, in connect\n    return _ConnectionFairy._checkout(self)\n  File "/home/truongtuananh/anaconda3/envs/resource-management/lib/python3.10/site-packages/sqlalchemy/pool/base.py", line 1271, in _checkout\n    fairy = _ConnectionRecord.checkout(pool)\n  File "/home/truongtuananh/anaconda3/envs/resource-management/lib/python3.10/site-packages/sqlalchemy/pool/base.py", line 719, in checkout\n    rec = pool._do_get()\n  File "/home/truongtuananh/anaconda3/envs/resource-management/lib/python3.10/site-packages/sqlalchemy/pool/impl.py", line 168, in _do_get\n    with util.safe_reraise():\n  File "/home/truongtuananh/anaconda3/envs/resource-management/lib/python3.10/site-packages/sqlalchemy/util/langhelpers.py", line 147, in __exit__\n    raise exc_value.with_traceback(exc_tb)\n  File "/home/truongtuananh/anaconda3/envs/resource-management/lib/python3.10/site-packages/sqlalchemy/pool/impl.py", line 166, in _do_get\n    return self._create_connection()\n  File "/home/truongtuananh/anaconda3/envs/resource-management/lib/python3.10/site-packages/sqlalchemy/pool/base.py", line 396, in _create_connection\n    return _ConnectionRecord(self)\n  File "/home/truongtuananh/anaconda3/envs/resource-management/lib/python3.10/site-packages/sqlalchemy/pool/base.py", line 681, in __init__\n    self.__connect()\n  File "/home/truongtuananh/anaconda3/envs/resource-management/lib/python3.10/site-packages/sqlalchemy/pool/base.py", line 905, in __connect\n    with util.safe_reraise():\n  File "/home/truongtuananh/anaconda3/envs/resource-management/lib/python3.10/site-packages/sqlalchemy/util/langhelpers.py", line 147, in __exit__\n    raise exc_value.with_traceback(exc_tb)\n  File "/home/truongtuananh/anaconda3/envs/resource-management/lib/python3.10/site-packages/sqlalchemy/pool/base.py", line 901, in __connect\n    self.dbapi_connection = connection = pool._invoke_creator(self)\n  File "/home/truongtuananh/anaconda3/envs/resource-management/lib/python3.10/site-packages/sqlalchemy/engine/create.py", line 641, in connect\n    return dialect.connect(*cargs, **cparams)\n  File "/home/truongtuananh/anaconda3/envs/resource-management/lib/python3.10/site-packages/sqlalchemy/engine/default.py", line 580, in connect\n    return self.loaded_dbapi.connect(*cargs, **cparams)\n  File "/home/truongtuananh/anaconda3/envs/resource-management/lib/python3.10/site-packages/psycopg2/__init__.py", line 122, in connect\n    conn = _connect(dsn, connection_factory=connection_factory, **kwasync)\npsycopg2.OperationalError: connection to server at "192.168.127.129", port 5432 failed: Connection refused\n\tIs the server running on that host and accepting TCP/IP connections?\n\n\nThe above exception was the direct cause of the following exception:\n\nTraceback (most recent call last):\n  File "/home/truongtuananh/Downloads/resource-management/app/../app/src/repositories/user_system.py", line 29, in get_user_by_email\n    self.model.is_deleted.is_(False)).first()\n  File "/home/truongtuananh/anaconda3/envs/resource-management/lib/python3.10/site-packages/sqlalchemy/orm/query.py", line 2752, in first\n    return self.limit(1)._iter().first()  # type: ignore\n  File "/home/truongtuananh/anaconda3/envs/resource-management/lib/python3.10/site-packages/sqlalchemy/orm/query.py", line 2855, in _iter\n    result: Union[ScalarResult[_T], Result[_T]] = self.session.execute(\n  File "/home/truongtuananh/anaconda3/envs/resource-management/lib/python3.10/site-packages/sqlalchemy/orm/session.py", line 2229, in execute\n    return self._execute_internal(\n  File "/home/truongtuananh/anaconda3/envs/resource-management/lib/python3.10/site-packages/sqlalchemy/orm/session.py", line 2114, in _execute_internal\n    conn = self._connection_for_bind(bind)\n  File "/home/truongtuananh/anaconda3/envs/resource-management/lib/python3.10/site-packages/sqlalchemy/orm/session.py", line 1981, in _connection_for_bind\n    return trans._connection_for_bind(engine, execution_options)\n  File "<string>", line 2, in _connection_for_bind\n  File "/home/truongtuananh/anaconda3/envs/resource-management/lib/python3.10/site-packages/sqlalchemy/orm/state_changes.py", line 137, in _go\n    ret_value = fn(self, *arg, **kw)\n  File "/home/truongtuananh/anaconda3/envs/resource-management/lib/python3.10/site-packages/sqlalchemy/orm/session.py", line 1108, in _connection_for_bind\n    conn = bind.connect()\n  File "/home/truongtuananh/anaconda3/envs/resource-management/lib/python3.10/site-packages/sqlalchemy/engine/base.py", line 3251, in connect\n    return self._connection_cls(self)\n  File "/home/truongtuananh/anaconda3/envs/resource-management/lib/python3.10/site-packages/sqlalchemy/engine/base.py", line 147, in __init__\n    Connection._handle_dbapi_exception_noconnection(\n  File "/home/truongtuananh/anaconda3/envs/resource-management/lib/python3.10/site-packages/sqlalchemy/engine/base.py", line 2413, in _handle_dbapi_exception_noconnection\n    raise sqlalchemy_exception.with_traceback(exc_info[2]) from e\n  File "/home/truongtuananh/anaconda3/envs/resource-management/lib/python3.10/site-packages/sqlalchemy/engine/base.py", line 145, in __init__\n    self._dbapi_connection = engine.raw_connection()\n  File "/home/truongtuananh/anaconda3/envs/resource-management/lib/python3.10/site-packages/sqlalchemy/engine/base.py", line 3275, in raw_connection\n    return self.pool.connect()\n  File "/home/truongtuananh/anaconda3/envs/resource-management/lib/python3.10/site-packages/sqlalchemy/pool/base.py", line 455, in connect\n    return _ConnectionFairy._checkout(self)\n  File "/home/truongtuananh/anaconda3/envs/resource-management/lib/python3.10/site-packages/sqlalchemy/pool/base.py", line 1271, in _checkout\n    fairy = _ConnectionRecord.checkout(pool)\n  File "/home/truongtuananh/anaconda3/envs/resource-management/lib/python3.10/site-packages/sqlalchemy/pool/base.py", line 719, in checkout\n    rec = pool._do_get()\n  File "/home/truongtuananh/anaconda3/envs/resource-management/lib/python3.10/site-packages/sqlalchemy/pool/impl.py", line 168, in _do_get\n    with util.safe_reraise():\n  File "/home/truongtuananh/anaconda3/envs/resource-management/lib/python3.10/site-packages/sqlalchemy/util/langhelpers.py", line 147, in __exit__\n    raise exc_value.with_traceback(exc_tb)\n  File "/home/truongtuananh/anaconda3/envs/resource-management/lib/python3.10/site-packages/sqlalchemy/pool/impl.py", line 166, in _do_get\n    return self._create_connection()\n  File "/home/truongtuananh/anaconda3/envs/resource-management/lib/python3.10/site-packages/sqlalchemy/pool/base.py", line 396, in _create_connection\n    return _ConnectionRecord(self)\n  File "/home/truongtuananh/anaconda3/envs/resource-management/lib/python3.10/site-packages/sqlalchemy/pool/base.py", line 681, in __init__\n    self.__connect()\n  File "/home/truongtuananh/anaconda3/envs/resource-management/lib/python3.10/site-packages/sqlalchemy/pool/base.py", line 905, in __connect\n    with util.safe_reraise():\n  File "/home/truongtuananh/anaconda3/envs/resource-management/lib/python3.10/site-packages/sqlalchemy/util/langhelpers.py", line 147, in __exit__\n    raise exc_value.with_traceback(exc_tb)\n  File "/home/truongtuananh/anaconda3/envs/resource-management/lib/python3.10/site-packages/sqlalchemy/pool/base.py", line 901, in __connect\n    self.dbapi_connection = connection = pool._invoke_creator(self)\n  File "/home/truongtuananh/anaconda3/envs/resource-management/lib/python3.10/site-packages/sqlalchemy/engine/create.py", line 641, in connect\n    return dialect.connect(*cargs, **cparams)\n  File "/home/truongtuananh/anaconda3/envs/resource-management/lib/python3.10/site-packages/sqlalchemy/engine/default.py", line 580, in connect\n    return self.loaded_dbapi.connect(*cargs, **cparams)\n  File "/home/truongtuananh/anaconda3/envs/resource-management/lib/python3.10/site-packages/psycopg2/__init__.py", line 122, in connect\n    conn = _connect(dsn, connection_factory=connection_factory, **kwasync)\nsqlalchemy.exc.OperationalError: (psycopg2.OperationalError) connection to server at "192.168.127.129", port 5432 failed: Connection refused\n\tIs the server running on that host and accepting TCP/IP connections?\n\n(Background on this error at: https://sqlalche.me/e/20/e3q8)\n'}
INFO     2024-03-14 18:50:41.634 request id: app - uvicorn.protocols.http.h11_impl:send - 127.0.0.1:38006 - "POST /rms/v1.0/login/access-token HTTP/1.1" 500
INFO     2024-03-14 18:53:08.170 request id: app - uvicorn.server:shutdown - Shutting down
INFO     2024-03-14 18:53:09.282 request id: app - uvicorn.lifespan.on:shutdown - Waiting for application shutdown.
INFO     2024-03-14 18:53:09.284 request id: app - uvicorn.lifespan.on:shutdown - Application shutdown complete.
INFO     2024-03-14 18:53:09.285 request id: app - uvicorn.server:serve - Finished server process [3694]
INFO     2024-03-16 07:31:01.307 request id: app - uvicorn.server:serve - Started server process [8561]
INFO     2024-03-16 07:31:01.311 request id: app - uvicorn.lifespan.on:startup - Waiting for application startup.
INFO     2024-03-16 07:31:01.313 request id: app - uvicorn.lifespan.on:startup - Application startup complete.
INFO     2024-03-16 07:31:22.678 request id: app - uvicorn.protocols.http.h11_impl:send - 127.0.0.1:52644 - "GET /docs HTTP/1.1" 200
INFO     2024-03-16 07:31:23.051 request id: app - uvicorn.protocols.http.h11_impl:send - 127.0.0.1:52646 - "GET /static/swagger-ui-bundle.js HTTP/1.1" 304
INFO     2024-03-16 07:31:23.055 request id: app - uvicorn.protocols.http.h11_impl:send - 127.0.0.1:52644 - "GET /static/swagger-ui.css HTTP/1.1" 200
INFO     2024-03-16 07:31:24.343 request id: app - uvicorn.protocols.http.h11_impl:send - 127.0.0.1:52644 - "GET /openapi.json HTTP/1.1" 200
INFO     2024-03-16 07:31:29.207 request id: app - uvicorn.protocols.http.h11_impl:send - 127.0.0.1:52644 - "GET / HTTP/1.1" 404
INFO     2024-03-16 07:31:29.643 request id: app - uvicorn.protocols.http.h11_impl:send - 127.0.0.1:52644 - "GET /favicon.ico HTTP/1.1" 404
INFO     2024-03-16 07:31:34.702 request id: app - uvicorn.protocols.http.h11_impl:send - 127.0.0.1:53214 - "GET /docs HTTP/1.1" 200
INFO     2024-03-16 07:31:35.163 request id: app - uvicorn.protocols.http.h11_impl:send - 127.0.0.1:53214 - "GET /openapi.json HTTP/1.1" 200
INFO     2024-03-16 07:33:23.123 request id: app - uvicorn.server:shutdown - Shutting down
INFO     2024-03-16 07:33:23.231 request id: app - uvicorn.lifespan.on:shutdown - Waiting for application shutdown.
INFO     2024-03-16 07:33:23.232 request id: app - uvicorn.lifespan.on:shutdown - Application shutdown complete.
INFO     2024-03-16 07:33:23.234 request id: app - uvicorn.server:serve - Finished server process [8561]
INFO     2024-03-16 07:33:25.903 request id: app - uvicorn.server:serve - Started server process [9215]
INFO     2024-03-16 07:33:25.911 request id: app - uvicorn.lifespan.on:startup - Waiting for application startup.
INFO     2024-03-16 07:33:25.913 request id: app - uvicorn.lifespan.on:startup - Application startup complete.
INFO     2024-03-16 07:33:25.929 request id: app - uvicorn.protocols.http.h11_impl:send - 127.0.0.1:60952 - "GET /docs HTTP/1.1" 200
INFO     2024-03-16 07:33:26.352 request id: app - uvicorn.protocols.http.h11_impl:send - 127.0.0.1:60956 - "GET /openapi.json HTTP/1.1" 200
INFO     2024-03-16 07:33:33.532 request id: app - uvicorn.server:shutdown - Shutting down
INFO     2024-03-16 07:33:33.636 request id: app - uvicorn.lifespan.on:shutdown - Waiting for application shutdown.
INFO     2024-03-16 07:33:33.637 request id: app - uvicorn.lifespan.on:shutdown - Application shutdown complete.
INFO     2024-03-16 07:33:33.639 request id: app - uvicorn.server:serve - Finished server process [9215]
INFO     2024-03-16 07:57:34.583 request id: app - uvicorn.server:serve - Started server process [9787]
INFO     2024-03-16 07:57:34.598 request id: app - uvicorn.lifespan.on:startup - Waiting for application startup.
INFO     2024-03-16 07:57:34.604 request id: app - uvicorn.lifespan.on:startup - Application startup complete.
INFO     2024-03-16 07:57:52.121 request id: app - uvicorn.protocols.http.h11_impl:send - 127.0.0.1:55302 - "GET / HTTP/1.1" 404
INFO     2024-03-16 07:57:53.669 request id: app - uvicorn.protocols.http.h11_impl:send - 127.0.0.1:55302 - "GET /favicon.ico HTTP/1.1" 404
INFO     2024-03-16 07:57:58.582 request id: app - uvicorn.protocols.http.h11_impl:send - 127.0.0.1:55302 - "GET /docs HTTP/1.1" 200
INFO     2024-03-16 07:58:01.159 request id: app - uvicorn.protocols.http.h11_impl:send - 127.0.0.1:55302 - "GET /openapi.json HTTP/1.1" 200
INFO     2024-03-16 07:58:47.263 request id: app - rbl_fastapi_base.base.base_router:custom_route_handler - {'headers': {'content-type': 'application/json'}, 'request_body': {'email': 'admin@rabiloo.com', 'password': 'Rabiloo@123'}}
ERROR    2024-03-16 07:58:47.401 request id: app - app.src.exceptions.exception_handler:business_exception_handler - Database Error
{'data': 'Traceback (most recent call last):\n  File "/home/truongtuananh/anaconda3/envs/resource-management/lib/python3.10/site-packages/sqlalchemy/engine/base.py", line 145, in __init__\n    self._dbapi_connection = engine.raw_connection()\n  File "/home/truongtuananh/anaconda3/envs/resource-management/lib/python3.10/site-packages/sqlalchemy/engine/base.py", line 3275, in raw_connection\n    return self.pool.connect()\n  File "/home/truongtuananh/anaconda3/envs/resource-management/lib/python3.10/site-packages/sqlalchemy/pool/base.py", line 455, in connect\n    return _ConnectionFairy._checkout(self)\n  File "/home/truongtuananh/anaconda3/envs/resource-management/lib/python3.10/site-packages/sqlalchemy/pool/base.py", line 1271, in _checkout\n    fairy = _ConnectionRecord.checkout(pool)\n  File "/home/truongtuananh/anaconda3/envs/resource-management/lib/python3.10/site-packages/sqlalchemy/pool/base.py", line 719, in checkout\n    rec = pool._do_get()\n  File "/home/truongtuananh/anaconda3/envs/resource-management/lib/python3.10/site-packages/sqlalchemy/pool/impl.py", line 168, in _do_get\n    with util.safe_reraise():\n  File "/home/truongtuananh/anaconda3/envs/resource-management/lib/python3.10/site-packages/sqlalchemy/util/langhelpers.py", line 147, in __exit__\n    raise exc_value.with_traceback(exc_tb)\n  File "/home/truongtuananh/anaconda3/envs/resource-management/lib/python3.10/site-packages/sqlalchemy/pool/impl.py", line 166, in _do_get\n    return self._create_connection()\n  File "/home/truongtuananh/anaconda3/envs/resource-management/lib/python3.10/site-packages/sqlalchemy/pool/base.py", line 396, in _create_connection\n    return _ConnectionRecord(self)\n  File "/home/truongtuananh/anaconda3/envs/resource-management/lib/python3.10/site-packages/sqlalchemy/pool/base.py", line 681, in __init__\n    self.__connect()\n  File "/home/truongtuananh/anaconda3/envs/resource-management/lib/python3.10/site-packages/sqlalchemy/pool/base.py", line 905, in __connect\n    with util.safe_reraise():\n  File "/home/truongtuananh/anaconda3/envs/resource-management/lib/python3.10/site-packages/sqlalchemy/util/langhelpers.py", line 147, in __exit__\n    raise exc_value.with_traceback(exc_tb)\n  File "/home/truongtuananh/anaconda3/envs/resource-management/lib/python3.10/site-packages/sqlalchemy/pool/base.py", line 901, in __connect\n    self.dbapi_connection = connection = pool._invoke_creator(self)\n  File "/home/truongtuananh/anaconda3/envs/resource-management/lib/python3.10/site-packages/sqlalchemy/engine/create.py", line 641, in connect\n    return dialect.connect(*cargs, **cparams)\n  File "/home/truongtuananh/anaconda3/envs/resource-management/lib/python3.10/site-packages/sqlalchemy/engine/default.py", line 580, in connect\n    return self.loaded_dbapi.connect(*cargs, **cparams)\n  File "/home/truongtuananh/anaconda3/envs/resource-management/lib/python3.10/site-packages/psycopg2/__init__.py", line 122, in connect\n    conn = _connect(dsn, connection_factory=connection_factory, **kwasync)\npsycopg2.OperationalError: connection to server at "192.168.127.129", port 5432 failed: Connection refused\n\tIs the server running on that host and accepting TCP/IP connections?\n\n\nThe above exception was the direct cause of the following exception:\n\nTraceback (most recent call last):\n  File "/home/truongtuananh/Downloads/resource-management/app/../app/src/repositories/user_system.py", line 20, in get_user_system_by_email\n    self.model.is_deleted.is_(False)).first()\n  File "/home/truongtuananh/anaconda3/envs/resource-management/lib/python3.10/site-packages/sqlalchemy/orm/query.py", line 2752, in first\n    return self.limit(1)._iter().first()  # type: ignore\n  File "/home/truongtuananh/anaconda3/envs/resource-management/lib/python3.10/site-packages/sqlalchemy/orm/query.py", line 2855, in _iter\n    result: Union[ScalarResult[_T], Result[_T]] = self.session.execute(\n  File "/home/truongtuananh/anaconda3/envs/resource-management/lib/python3.10/site-packages/sqlalchemy/orm/session.py", line 2229, in execute\n    return self._execute_internal(\n  File "/home/truongtuananh/anaconda3/envs/resource-management/lib/python3.10/site-packages/sqlalchemy/orm/session.py", line 2114, in _execute_internal\n    conn = self._connection_for_bind(bind)\n  File "/home/truongtuananh/anaconda3/envs/resource-management/lib/python3.10/site-packages/sqlalchemy/orm/session.py", line 1981, in _connection_for_bind\n    return trans._connection_for_bind(engine, execution_options)\n  File "<string>", line 2, in _connection_for_bind\n  File "/home/truongtuananh/anaconda3/envs/resource-management/lib/python3.10/site-packages/sqlalchemy/orm/state_changes.py", line 137, in _go\n    ret_value = fn(self, *arg, **kw)\n  File "/home/truongtuananh/anaconda3/envs/resource-management/lib/python3.10/site-packages/sqlalchemy/orm/session.py", line 1108, in _connection_for_bind\n    conn = bind.connect()\n  File "/home/truongtuananh/anaconda3/envs/resource-management/lib/python3.10/site-packages/sqlalchemy/engine/base.py", line 3251, in connect\n    return self._connection_cls(self)\n  File "/home/truongtuananh/anaconda3/envs/resource-management/lib/python3.10/site-packages/sqlalchemy/engine/base.py", line 147, in __init__\n    Connection._handle_dbapi_exception_noconnection(\n  File "/home/truongtuananh/anaconda3/envs/resource-management/lib/python3.10/site-packages/sqlalchemy/engine/base.py", line 2413, in _handle_dbapi_exception_noconnection\n    raise sqlalchemy_exception.with_traceback(exc_info[2]) from e\n  File "/home/truongtuananh/anaconda3/envs/resource-management/lib/python3.10/site-packages/sqlalchemy/engine/base.py", line 145, in __init__\n    self._dbapi_connection = engine.raw_connection()\n  File "/home/truongtuananh/anaconda3/envs/resource-management/lib/python3.10/site-packages/sqlalchemy/engine/base.py", line 3275, in raw_connection\n    return self.pool.connect()\n  File "/home/truongtuananh/anaconda3/envs/resource-management/lib/python3.10/site-packages/sqlalchemy/pool/base.py", line 455, in connect\n    return _ConnectionFairy._checkout(self)\n  File "/home/truongtuananh/anaconda3/envs/resource-management/lib/python3.10/site-packages/sqlalchemy/pool/base.py", line 1271, in _checkout\n    fairy = _ConnectionRecord.checkout(pool)\n  File "/home/truongtuananh/anaconda3/envs/resource-management/lib/python3.10/site-packages/sqlalchemy/pool/base.py", line 719, in checkout\n    rec = pool._do_get()\n  File "/home/truongtuananh/anaconda3/envs/resource-management/lib/python3.10/site-packages/sqlalchemy/pool/impl.py", line 168, in _do_get\n    with util.safe_reraise():\n  File "/home/truongtuananh/anaconda3/envs/resource-management/lib/python3.10/site-packages/sqlalchemy/util/langhelpers.py", line 147, in __exit__\n    raise exc_value.with_traceback(exc_tb)\n  File "/home/truongtuananh/anaconda3/envs/resource-management/lib/python3.10/site-packages/sqlalchemy/pool/impl.py", line 166, in _do_get\n    return self._create_connection()\n  File "/home/truongtuananh/anaconda3/envs/resource-management/lib/python3.10/site-packages/sqlalchemy/pool/base.py", line 396, in _create_connection\n    return _ConnectionRecord(self)\n  File "/home/truongtuananh/anaconda3/envs/resource-management/lib/python3.10/site-packages/sqlalchemy/pool/base.py", line 681, in __init__\n    self.__connect()\n  File "/home/truongtuananh/anaconda3/envs/resource-management/lib/python3.10/site-packages/sqlalchemy/pool/base.py", line 905, in __connect\n    with util.safe_reraise():\n  File "/home/truongtuananh/anaconda3/envs/resource-management/lib/python3.10/site-packages/sqlalchemy/util/langhelpers.py", line 147, in __exit__\n    raise exc_value.with_traceback(exc_tb)\n  File "/home/truongtuananh/anaconda3/envs/resource-management/lib/python3.10/site-packages/sqlalchemy/pool/base.py", line 901, in __connect\n    self.dbapi_connection = connection = pool._invoke_creator(self)\n  File "/home/truongtuananh/anaconda3/envs/resource-management/lib/python3.10/site-packages/sqlalchemy/engine/create.py", line 641, in connect\n    return dialect.connect(*cargs, **cparams)\n  File "/home/truongtuananh/anaconda3/envs/resource-management/lib/python3.10/site-packages/sqlalchemy/engine/default.py", line 580, in connect\n    return self.loaded_dbapi.connect(*cargs, **cparams)\n  File "/home/truongtuananh/anaconda3/envs/resource-management/lib/python3.10/site-packages/psycopg2/__init__.py", line 122, in connect\n    conn = _connect(dsn, connection_factory=connection_factory, **kwasync)\nsqlalchemy.exc.OperationalError: (psycopg2.OperationalError) connection to server at "192.168.127.129", port 5432 failed: Connection refused\n\tIs the server running on that host and accepting TCP/IP connections?\n\n(Background on this error at: https://sqlalche.me/e/20/e3q8)\n'}
INFO     2024-03-16 07:58:47.403 request id: app - uvicorn.protocols.http.h11_impl:send - 127.0.0.1:44912 - "POST /Resource-Management/user-system/login/access-token HTTP/1.1" 500
INFO     2024-03-16 08:03:23.361 request id: app - uvicorn.server:shutdown - Shutting down
INFO     2024-03-16 08:03:23.465 request id: app - uvicorn.lifespan.on:shutdown - Waiting for application shutdown.
INFO     2024-03-16 08:03:23.466 request id: app - uvicorn.lifespan.on:shutdown - Application shutdown complete.
INFO     2024-03-16 08:03:23.468 request id: app - uvicorn.server:serve - Finished server process [9787]
INFO     2024-03-28 22:58:30.109 request id: app - uvicorn.server:serve - Started server process [28717]
INFO     2024-03-28 22:58:31.153 request id: app - uvicorn.lifespan.on:startup - Waiting for application startup.
INFO     2024-03-28 22:58:32.356 request id: app - uvicorn.lifespan.on:startup - Application startup complete.
INFO     2024-03-28 22:58:33.654 request id: app - uvicorn.server:shutdown - Shutting down
INFO     2024-03-28 22:59:37.395 request id: app - uvicorn.server:serve - Started server process [28945]
INFO     2024-03-28 22:59:38.410 request id: app - uvicorn.lifespan.on:startup - Waiting for application startup.
INFO     2024-03-28 22:59:39.421 request id: app - uvicorn.lifespan.on:startup - Application startup complete.
INFO     2024-03-28 22:59:50.508 request id: app - uvicorn.server:shutdown - Shutting down
INFO     2024-03-28 22:59:51.625 request id: app - uvicorn.lifespan.on:shutdown - Waiting for application shutdown.
INFO     2024-03-28 22:59:51.646 request id: app - uvicorn.lifespan.on:shutdown - Application shutdown complete.
INFO     2024-03-28 22:59:51.673 request id: app - uvicorn.server:serve - Finished server process [28945]
